Traceback (most recent call last):
  File "/home/user/.local/lib/python3.8/site-packages/jupyter_cache/executors/utils.py", line 51, in single_nb_execution
    executenb(
  File "/usr/local/lib/python3.8/dist-packages/nbclient/client.py", line 1082, in execute
    return NotebookClient(nb=nb, resources=resources, km=km, **kwargs).execute()
  File "/usr/local/lib/python3.8/dist-packages/nbclient/util.py", line 74, in wrapped
    return just_run(coro(*args, **kwargs))
  File "/usr/local/lib/python3.8/dist-packages/nbclient/util.py", line 53, in just_run
    return loop.run_until_complete(coro)
  File "/usr/lib/python3.8/asyncio/base_events.py", line 616, in run_until_complete
    return future.result()
  File "/usr/local/lib/python3.8/dist-packages/nbclient/client.py", line 535, in async_execute
    await self.async_execute_cell(
  File "/usr/local/lib/python3.8/dist-packages/nbclient/client.py", line 827, in async_execute_cell
    self._check_raise_for_error(cell, exec_reply)
  File "/usr/local/lib/python3.8/dist-packages/nbclient/client.py", line 735, in _check_raise_for_error
    raise CellExecutionError.from_cell_and_msg(cell, exec_reply['content'])
nbclient.exceptions.CellExecutionError: An error occurred while executing the following cell:
------------------
G = get_lattice(20, 2)
plt.figure(figsize=(3,3), dpi=25)
nx.draw(G, with_labels=True)

rewire_edge(G, 0, 1)
plt.figure(figsize=(3,3), dpi=25)
nx.draw(G, with_labels=True)
------------------

[0;31m---------------------------------------------------------------------------[0m
[0;31mTypeError[0m                                 Traceback (most recent call last)
[0;32m/tmp/ipykernel_2872/3294834332.py[0m in [0;36m<module>[0;34m[0m
[1;32m      1[0m [0mG[0m [0;34m=[0m [0mget_lattice[0m[0;34m([0m[0;36m20[0m[0;34m,[0m [0;36m2[0m[0;34m)[0m[0;34m[0m[0;34m[0m[0m
[0;32m----> 2[0;31m [0mplt[0m[0;34m.[0m[0mfigure[0m[0;34m([0m[0mfigsize[0m[0;34m=[0m[0;34m([0m[0;36m3[0m[0;34m,[0m[0;36m3[0m[0;34m)[0m[0;34m,[0m [0mdpi[0m[0;34m=[0m[0;36m25[0m[0;34m)[0m[0;34m[0m[0;34m[0m[0m
[0m[1;32m      3[0m [0mnx[0m[0;34m.[0m[0mdraw[0m[0;34m([0m[0mG[0m[0;34m,[0m [0mwith_labels[0m[0;34m=[0m[0;32mTrue[0m[0;34m)[0m[0;34m[0m[0;34m[0m[0m
[1;32m      4[0m [0;34m[0m[0m
[1;32m      5[0m [0mrewire_edge[0m[0;34m([0m[0mG[0m[0;34m,[0m [0;36m0[0m[0;34m,[0m [0;36m1[0m[0;34m)[0m[0;34m[0m[0;34m[0m[0m

[0;31mTypeError[0m: new_figure() got an unexpected keyword argument 'dpi'
TypeError: new_figure() got an unexpected keyword argument 'dpi'

